<?xml version="1.0"?>
<robot name = "opendog">

  <!-- CTRL + Backslash to comment -->

<!-- gazebo plugins go here -->
    <gazebo>
        <plugin name="gazebo_ros_control" filename="libgazebo_ros_control.so">
            <robotNamespace>/opendog</robotNamespace>
        </plugin>
    </gazebo>

	<material name="blue">
        <color rgba="0 0 0.8 1"/>
    </material>

    <material name="red">
        <color rgba="0.8 0 0 1"/>
    </material>

    <material name="green">
        <color rgba="0 0.8 0 1"/>
    </material>

    <material name="grey">
        <color rgba="0.75 0.75 0.75 1"/>
    </material>

    <material name="white">
        <color rgba="1.0 1.0 1.0 1"/>
    </material>

    <material name="black">
        <color rgba="0 0 0 1"/>
    </material>

 
    <link name = "openDog_body">
    	<visual>
    		<origin xyz = "0 0 0.7" rpy = "0 0 0"/>
    		<geometry>
    			<box size = "0.31 0.881 0.195"/>
    		</geometry>
    		<material name = "blue"/>
    	</visual>
        <collision>
            <origin xyz = "0 0 0.7" rpy = "0 0 0"/>
            <geometry>
                <box size = "0.31 0.881 0.195"/>
            </geometry>
        </collision>
         <inertial>
       <origin xyz = "0 0 0.7" rpy = "0 0 0"/>
    <mass value="24.326"/>
      <inertia
        ixx="2.44310079067" ixy="0.0" ixz="0.0"
        iyy="0.402464416667" iyz="0.0"
        izz="2.61736450733"/>
    </inertial>
    </link> 
 
      <link name = "dummy_mass"> 
        <visual>
            <origin xyz = "0 0 0" rpy = "0 0 0"/>
            <geometry>
                <box size = "0.31 0.881 0.195 "/>
            </geometry>
            <material name = "black"/>
        </visual>
        <collision>
            <origin xyz = "0 0 0" rpy = "0 0 0"/>
            <geometry>
                <box size = "0.31 0.881 0.195"/>
            </geometry>
        </collision>
        <inertial>
       <origin xyz = "0 0 0.7" rpy = "0 0 0"/>
    <mass value="24.326"/>
      <inertia
        ixx="2.44310079067" ixy="0.0" ixz="0.0"
        iyy="0.402464416667" iyz="0.0"
        izz="2.61736450733"/>
    </inertial>
    </link>  
    

    <link name = "hip_tube_1">
    	<visual>
    		<origin xyz = "0.0 0.0 0.0" rpy = "0 1.5708 0"/>
    		<geometry>
    			<cylinder length = "0.165" radius = "0.05715"/>
    		</geometry>
    		<material name = "green"/>
    	</visual>
        <collision>
            <origin xyz = "0.0 0.0 0.0" rpy = "0 1.5708 0"/>
            <geometry>
                <cylinder length = "0.165" radius = "0.05715"/>
            </geometry>
        </collision>
        <inertial>
       <origin xyz = "0.0 0.0 0.0" rpy = "0 1.5708 0"/>
    <mass value="1"/>
      <inertia
        ixx="1.0" ixy="0.0" ixz="0.0"
        iyy="1.0" iyz="0.0"
        izz="1.0"/>
    </inertial>
    </link> 
<!-- 
    <link name = "hip_tube_2">
    	<visual>
    		<origin xyz = "0.0 0.0 0.0" rpy = "0 1.5708 0"/>
    		<geometry>
    			<cylinder length = "0.165" radius = "0.05715"/>
    		</geometry>
    		<material name = "green"/>
    	</visual>
        <collision>
            <origin xyz = "0.0 0.0 0.0" rpy = "0 1.5708 0"/>
            <geometry>
                <cylinder length = "0.165" radius = "0.05715"/>
            </geometry>
        </collision>
        <inertial>
       <origin xyz = "0.0 0.0 0.0" rpy = "0 1.5708 0"/>
    <mass value="1"/>
      <inertia
        ixx="1.0" ixy="0.0" ixz="0.0"
        iyy="1.0" iyz="0.0"
        izz="1.0"/>
    </inertial>
    </link> -->
<!-- 
    <link name = "hip_tube_3">
    	<visual>
    		<origin xyz = "0.0 0.0 0.0" rpy = "0 1.5708 0"/>
    		<geometry>
    			<cylinder length = "0.165" radius = "0.05715"/>
    		</geometry>
    		<material name = "green"/>
    	</visual>
        <collision>
            <origin xyz = "0.0 0.0 0.0" rpy = "0 1.5708 0"/>
            <geometry>
                <cylinder length = "0.165" radius = "0.05715"/>
            </geometry>
        </collision>
        <inertial>
       <origin xyz = "0.0 0.0 0.0" rpy = "0 1.5708 0"/>
    <mass value="1"/>
      <inertia
        ixx="1.0" ixy="0.0" ixz="0.0"
        iyy="1.0" iyz="0.0"
        izz="1.0"/>
    </inertial>
    </link> -->
<!-- 
    <link name = "hip_tube_4">
    	<visual>
    		<origin xyz = "0.0 0.0 0.0" rpy = "0 1.5708 0"/>
    		<geometry>
    			<cylinder length = "0.165" radius = "0.05715"/>
    		</geometry>
    		<material name = "green"/>
    	</visual>
        <collision>
            <origin xyz = "0.0 0.0 0.0" rpy = "0 1.5708 0"/>
            <geometry>
                <cylinder length = "0.165" radius = "0.05715"/>
            </geometry>
        </collision>
        <inertial>
       <origin xyz = "0.0 0.0 0.0" rpy = "0 1.5708 0"/>
    <mass value="1"/>
      <inertia
        ixx="1.0" ixy="0.0" ixz="0.0"
        iyy="1.0" iyz="0.0"
        izz="1.0"/>
    </inertial>
    </link> -->



	<link name = "lower_extrusion_leg1">
		<visual>
			<origin xyz = "0.0 0.155 0.0" rpy = "1.5708 3.14 0"/>
			<geometry>
			 	<box size = "0.02 0.04 0.31"/>
			</geometry>
			<material name = "grey"/>
		</visual>
        <collision>
            <origin xyz = "0.0 0.155 0.0" rpy = "1.5708 3.14 0"/>
            <geometry>
                <box size = "0.02 0.04 0.31"/>
            </geometry>
        </collision>
        <inertial>
        <origin xyz = "0.0 0.155 0.0" rpy = "1.5708 3.14 0"/>
    <mass value="2.224"/>
      <inertia
        ixx="0.01566066666667" ixy="0.0" ixz="0.0"
        iyy="0.0156050666667" iyz="0.0"
        izz="9.26666666667e-05"/>
    </inertial>
	</link>
<!-- 
 <link name = "lower_extrusion_leg2">
		<visual>
			<origin xyz = "0.0 0.155 0.0" rpy = "1.5708 3.14 0"/>
			<geometry>
			 	<box size = "0.02 0.04 0.31"/>
			</geometry>
			<material name = "grey"/>
		</visual>
        <collision>
            <origin xyz = "0.0 0.155 0.0" rpy = "1.5708 3.14 0"/>
            <geometry>
                <box size = "0.02 0.04 0.31"/>
            </geometry>

        </collision>
        <inertial>
        <origin xyz = "0.0 0.155 0.0" rpy = "1.5708 3.14 0"/>
    <mass value="2.224"/>
      <inertia
        ixx="0.01566066666667" ixy="0.0" ixz="0.0"
        iyy="0.0156050666667" iyz="0.0"
        izz="9.26666666667e-05"/>
    </inertial>

	</link>  -->
<!-- 
	<link name = "lower_extrusion_leg3">
		<visual>
			<origin xyz = "0.0 0.155 0.0" rpy = "1.5708 3.14 0"/>
			<geometry>
			 	<box size = "0.02 0.04 0.31"/>
			</geometry>
			<material name = "grey"/>
		</visual>
        <collision>
            <origin xyz = "0.0 0.155 0.0" rpy = "1.5708 3.14 0"/>
            <geometry>
                <box size = "0.02 0.04 0.31"/>
            </geometry>
        </collision>
        <inertial>
        <origin xyz = "0.0 0.155 0.0" rpy = "1.5708 3.14 0"/>
    <mass value="2.224"/>
      <inertia
        ixx="0.01566066666667" ixy="0.0" ixz="0.0"
        iyy="0.0156050666667" iyz="0.0"
        izz="9.26666666667e-05"/>
    </inertial>
	</link> -->
<!-- 
	<link name = "lower_extrusion_leg4">
		<visual>
			<origin xyz = "0.0 0.155 0.0" rpy = "1.5708 3.14 0"/>
			<geometry>
			 	<box size = "0.02 0.04 0.31"/>
			</geometry>
			<material name = "grey"/>
		</visual>
        <collision>
            <origin xyz = "0.0 0.155 0.0" rpy = "1.5708 3.14 0"/>
            <geometry>
                <box size = "0.02 0.04 0.31"/>
            </geometry>
        </collision>
        <inertial>
    <origin xyz = "0.0 0.155 0.0" rpy = "1.5708 3.14 0"/>
    <mass value="2.224"/>
      <inertia
        ixx="0.01566066666667" ixy="0.0" ixz="0.0"
        iyy="0.0156050666667" iyz="0.0"
        izz="9.26666666667e-05"/>
    </inertial>
	</link> -->


	<link name = "upper_extrusion_leg1">
		<visual>
			<origin xyz = "0.0 0.195 0.0" rpy = "1.5708 0 0"/>
			<geometry>
				<box size = "0.02 0.06 0.39"/>
			</geometry>
			<material name = "red"/>
		</visual>
        <collision>
            <origin xyz = "0.0 0.195 0.0" rpy = "1.5708 0 0"/>
            <geometry>
                <box size = "0.02 0.06 0.39"/>
            </geometry>
            <material name = "red"/>
        </collision>
        <inertial>
    <origin xyz = "0.0 0.195 0.0" rpy = "1.5708 0 0"/>
    <mass value="4.036"/>
      <inertia
        ixx="0.013091775" ixy="0.0" ixz="0.0"
        iyy="0.000336333333333" iyz="0.0"
        izz="0.0128227083333"/>
    </inertial>
	</link>
<!-- 
	<link name = "upper_extrusion_leg2">
		<visual>
			<origin xyz = "0.0 0.195 0.0" rpy = "1.5708 0 0"/>
			<geometry>
				<box size = "0.02 0.06 0.39"/>
			</geometry>
			<material name = "red"/>
		</visual>
        <collision>
            <origin xyz = "0.0 0.195 0.0" rpy = "1.5708 0 0"/>
            <geometry>
                <box size = "0.02 0.06 0.39"/>
            </geometry>
            <material name = "red"/>
        </collision>
        <inertial>
    <origin xyz = "0.0 0.195 0.0" rpy = "1.5708 0 0"/>
    <mass value="4.036"/>
      <inertia
        ixx="0.013091775" ixy="0.0" ixz="0.0"
        iyy="0.000336333333333" iyz="0.0"
        izz="0.0128227083333"/>
    </inertial>
	</link> -->
<!-- 
	<link name = "upper_extrusion_leg3">
		<visual>
			<origin xyz = "0.0 0.195 0.0" rpy = "1.5708 0 0"/>
			<geometry>
				<box size = "0.02 0.06 0.39"/>
			</geometry>
			<material name = "red"/>
		</visual>
        <collision>
            <origin xyz = "0.0 0.195 0.0" rpy = "1.5708 0 0"/>
            <geometry>
                <box size = "0.02 0.06 0.39"/>
            </geometry>
            <material name = "red"/>
        </collision>
    <inertial>
      <origin xyz = "0.0 0.195 0.0" rpy = "1.5708 0 0"/>
      <mass value="4.036"/>
        <inertia
          ixx="0.013091775" ixy="0.0" ixz="0.0"
          iyy="0.000336333333333" iyz="0.0"
          izz="0.0128227083333"/>
    </inertial>
	</link> -->

<!-- 
	<link name = "upper_extrusion_leg4">
		<visual>
			<origin xyz = "0.0 0.195 0.0" rpy = "1.5708 0 0"/>
			<geometry>
				<box size = "0.02 0.06 0.39"/>
			</geometry>
			<material name = "red"/>
		</visual>
        <collision>
            <origin xyz = "0.0 0.195 0.0" rpy = "1.5708 0 0"/>
            <geometry>
                <box size = "0.02 0.06 0.39"/>
            </geometry>
            <material name = "red"/>
        </collision>
    <inertial>
      <origin xyz = "0.0 0.195 0.0" rpy = "1.5708 0 0"/>
      <mass value="4.036"/>
        <inertia
          ixx="0.013091775" ixy="0.0" ixz="0.0"
          iyy="0.000336333333333" iyz="0.0"
          izz="0.0128227083333"/>
    </inertial>
	</link>    -->

  <!-- knee links  -->
       <link name = "knee1">
      <visual>
        <origin xyz = "0 0 0" rpy = "0 0 0"/>
        <geometry>
          <box size = ".04 0.0303 .13"/>
          </geometry>
          <material name = "red"/>
      </visual>
        <collision>
          <origin xyz = "0 0 0" rpy = "0 0 0"/>
          <geometry>
            <box size = ".04 0.0303 .13"/>
            </geometry>
            <material name = "red"/>
          </collision>
      <inertial>
      <origin xyz = "0 0 0" rpy = "0 0 0"/>
        <mass value="0.187164"/>
        <inertia
          ixx="1" ixy="1" ixz="1"
          iyy="1" iyz="1"
          izz="1"/>
      </inertial>
   </link> 
<!-- 
   <link name = "knee2">
     <visual>
     <origin xyz = "" rpy = ""/>
     <geometry>
       <box size = ".04 0.0303 .13"/>
       </geometry>
       <material name = "red"/>
     </visual>
       <collision>
         <origin xyz = "" rpy = ""/>
         <geometry>
           <box size = ".04 0.0303 .13"/>
           </geometry>
           <material name = "red"/>
         </collision>
     <inertial>
       <origin xyz = "" rpy = ""/>
       <mass value="0.187164"/>
       <inertia
         ixx="" ixy="" ixz=""
         iyy="" iyz=""
         izz=""/>
     </inertial>
  </link>

  <link name = "knee3">
    <visual>
    <origin xyz = "" rpy = ""/>
    <geometry>
      <box size = ".04 0.0303 .13"/>
      </geometry>
      <material name = "red"/>
    </visual>
      <collision>
        <origin xyz = "" rpy = ""/>
        <geometry>
          <box size = ".04 0.0303 .13"/>
          </geometry>
          <material name = "red"/>
        </collision>
    <inertial>
      <origin xyz = "" rpy = ""/>
      <mass value="0.187164"/>
      <inertia
        ixx="" ixy="" ixz=""
        iyy="" iyz=""
        izz=""/>
    </inertial>
  </link>

  <link name = "knee4">
    <visual>
    <origin xyz = "" rpy = ""/>
    <geometry>
      <box size = ".04 0.0303 .13"/>
      </geometry>
      <material name = "red"/>
    </visual>
      <collision>
        <origin xyz = "" rpy = ""/>
        <geometry>
          <box size = ".04 0.0303 .13"/>
          </geometry>
          <material name = "red"/>
        </collision>
    <inertial>
      <origin xyz = "" rpy = ""/>
      <mass value="0.187164"/>
      <inertia
        ixx="" ixy="" ixz=""
        iyy="" iyz=""
        izz=""/>
    </inertial>
  </link> -->


  <!-- Slide Block Links -->
  <!-- Tibia -->
     <link name = "SlideBlock1_1">
    <visual>
      <origin xyz = "0 0 0" rpy = "0 0 0"/>
      <geometry>
        <box size = ".078 0.0534 0.044"/>
        </geometry>
        <material name = "red"/>
      </visual>
      <collision>
        <origin xyz = "0 0 0" rpy = "0 0 0"/>
        <geometry>
          <box size = ".078 0.0534 0.044"/>
          </geometry>
          <material name = "red"/>
        </collision>
      <inertial>
        <origin xyz = "0 0 0" rpy = "0 0 0"/>
        <mass value="0.0251964"/>
        <inertia
          ixx="1" ixy="1" ixz="1"
          iyy="1" iyz="1"
          izz="1"/>
      </inertial>
  </link>   

  <!-- Femur -->
    <link name = "SlideBlock1_2">
    <visual>
      <origin xyz = "0 0 0" rpy = "0 0 0"/>
      <geometry>
        <box size = ".078 0.0534 0.044"/>
      </geometry>
        <material name = "red"/>
      </visual>
      <collision>
        <origin xyz = "0 0 0" rpy = "0 0 0"/>
        <geometry>
          <box size = ".078 0.0534 0.044"/>
        </geometry>
          <material name = "red"/>
      </collision>
    <inertial>
      <origin xyz = "0 0 0" rpy = "0 0 0"/>
      <mass value="0.0251964"/>
      <inertia
        ixx="1" ixy="1" ixz="1"
        iyy="1" iyz="1"
        izz="1"/>
    </inertial>
  </link>  

  <!-- <link name = "SlideBlock2_1">
    <visual>
    <origin xyz = "" rpy = ""/>
    <geometry>
      <box size = ".078 0.0534 0.044"/>
      </geometry>
      <material name = "red"/>
    </visual>
      <collision>
        <origin xyz = "" rpy = ""/>
        <geometry>
          <box size = ".078 0.0534 0.044"/>
          </geometry>
          <material name = "red"/>
        </collision>
    <inertial>
    <origin xyz = "" rpy = ""/>
    <mass value="0.0251964"/>
    <inertia
      ixx="" ixy="" ixz=""
      iyy="" iyz=""
      izz=""/>
    </inertial>
  </link>

  <link name = "SlideBlock2_2">
    <visual>
    <origin xyz = "" rpy = ""/>
    <geometry>
      <box size = ".078 0.0534 0.044"/>
    </geometry>
      <material name = "red"/>
    </visual>
      <collision>
        <origin xyz = "" rpy = ""/>
        <geometry>
          <box size = ".078 0.0534 0.044"/>
        </geometry>
          <material name = "red"/>
        </collision>
    <inertial>
    <origin xyz = "" rpy = ""/>
    <mass value="0.0251964"/>
    <inertia
      ixx="" ixy="" ixz=""
      iyy="" iyz=""
      izz=""/>
    </inertial>
  </link>  -->


  <!-- Screw on which Slide Block acctuates -->
   <link name = "Screw1">
    <visual>
      <origin xyz = "0 0 0" rpy = "0 0 0"/>
      <geometry>
        <cylinder radius = "0.0075" length = "0.25"/>
      </geometry>
        <material name = "grey"/>
      </visual>
      <collision>
        <origin xyz = "0 0 0" rpy = "0 0 0"/>
        <geometry>
          <cylinder radius = "0.0075" length = "0.25"/>
        </geometry>
          <material name = "red"/>
      </collision>
    <inertial>
      <origin xyz = "0 0 0" rpy = "0 0 0"/>
       <mass value="0.044228"/>
      <inertia
        ixx="0" ixy="0" ixz="0"
        iyy="0" iyz="0"
        izz="0"/>
    </inertial>
  </link> 

  <link name = "Screw2">
    <visual>
      <origin xyz = "0 0 0" rpy = "0 0 0"/>
      <geometry>
        <cylinder radius = "0.0075" length = "0.25"/>
      </geometry>
        <material name = "grey"/>
      </visual>
      <collision>
        <origin xyz = "0 0 0" rpy = "0 0 0"/>
        <geometry>
          <cylinder radius = "0.0075" length = "0.25"/>
        </geometry>
          <material name = "red"/>
      </collision>
    <inertial>
      <origin xyz = "0 0 0" rpy = "0 0 0"/>
       <mass value="0.044228"/>
      <inertia
        ixx="0" ixy="0" ixz="0"
        iyy="0" iyz="0"
        izz="0"/>
    </inertial>
  </link> 


    <!-- M10 Screw inserted into Slide Block -->
    <!-- Tibia -->
     <link name = "M10ScrewFemur1_1">
      <visual>
        <origin xyz = "0 0 0" rpy = "0 0 0"/>
        <geometry>
          <cylinder radius = "0.005" length = "0.05"/>
        </geometry>
          <material name = "grey"/>
        </visual>
        <collision>
          <origin xyz = "0 0 0" rpy = "0 0 0"/>
          <geometry>
            <cylinder radius = "0.005" length = "0.05"/>
          </geometry>
            <material name = "grey"/>
        </collision>
      <inertial>
        <origin xyz = "0 0 0" rpy = "0 0 0"/>
        <mass value="0"/>
        <inertia
          ixx="1" ixy="1" ixz="1"
          iyy="1" iyz="1"
          izz="1"/>
      </inertial>
    </link>

    <link name = "M10ScrewFemur1_2">
      <visual>
        <origin xyz = "0 0 0" rpy = "0 0 0"/>
        <geometry>
          <cylinder radius = "0.005" length = "0.05"/>
        </geometry>
          <material name = "grey"/>
        </visual>
        <collision>
          <origin xyz = "0 0 0" rpy = "0 0 0"/>
          <geometry>
            <cylinder radius = "0.005" length = "0.05"/>
          </geometry>
            <material name = "grey"/>
        </collision>
      <inertial>
        <origin xyz = "0 0 0" rpy = "0 0 0"/>
        <mass value="0"/>
        <inertia
          ixx="1" ixy="1" ixz="1"
          iyy="1" iyz="1"
          izz="1"/>
      </inertial>
    </link> 

     <!-- Femur  -->
    <link name = "M10ScrewFemur1_3">
      <visual>
        <origin xyz = "0 0 0" rpy = "0 0 0"/>
        <geometry>
          <cylinder radius = "0.005" length = "0.05"/>
        </geometry>
          <material name = "grey"/>
        </visual>
        <collision>
          <origin xyz = "0 0 0" rpy = "0 0 0"/>
          <geometry>
            <cylinder radius = "0.005" length = "0.05"/>
          </geometry>
            <material name = "grey"/>
        </collision>
      <inertial>
        <origin xyz = "0 0 0" rpy = "0 0 0"/>
        <mass value="0"/>
        <inertia
          ixx="1" ixy="1" ixz="1"
          iyy="1" iyz="1"
          izz="1"/>
      </inertial>
    </link> 
 
    <link name = "M10ScrewFemur1_4">
      <visual>
        <origin xyz = "0 0 0" rpy = "0 0 0"/>
        <geometry>
          <cylinder radius = "0.005" length = "0.05"/>
        </geometry>
          <material name = "grey"/>
        </visual>
        <collision>
          <origin xyz = "0 0 0" rpy = "0 0 0"/>
          <geometry>
            <cylinder radius = "0.005" length = "0.05"/>
          </geometry>
            <material name = "grey"/>
        </collision>
      <inertial>
        <origin xyz = "0 0 0" rpy = "0 0 0"/>
        <mass value="0"/>
        <inertia
          ixx="1" ixy="1" ixz="1"
          iyy="1" iyz="1"
          izz="1"/>
      </inertial>
    </link>  

    <!-- <link name = "M10Screw2_1">
      <visual>
        <origin xyz = "" rpy = ""/>
        <geometry>
          <cylinder radius = "0.005" length = "0.05"/>
        </geometry>
          <material name = "red"/>
        </visual>
        <collision>
          <origin xyz = "" rpy = ""/>
          <geometry>
            <cylinder radius = "0.005" length = "0.1"/>
          </geometry>
            <material name = "red"/>
        </collision>
      <inertial>
      <origin xyz = "" rpy = ""/>
      <mass value=""/>
      <inertia
        ixx="" ixy="" ixz=""
        iyy="" iyz=""
        izz=""/>
      </inertial>
    </link>   -->


    <!-- M10 Screw inserted through Knee -->
     <link name = "M10Knee1_1">
      <visual>
        <origin xyz = "0 0 0" rpy = "0 0 0"/>
        <geometry>
          <cylinder radius = "0.005" length = "0.1471"/>
        </geometry>
          <material name = "grey"/>
        </visual>
        <collision>
          <origin xyz = "0 0 0" rpy = "0 0 0"/>
          <geometry>
            <cylinder radius = "0.005" length = "0.1471"/>
          </geometry>
            <material name = "red"/>
        </collision>
      <inertial>
        <origin xyz = "0 0 0" rpy = "0 0 0"/>
        <mass value="0.1"/>
        <inertia
          ixx="0.1" ixy="0" ixz="0"
          iyy="0" iyz="0"
          izz="0"/>
      </inertial>
    </link>
<!-- 
    <link name = "M10Knee1.2">
      <visual>
        <origin xyz = "0 0 0" rpy = "0 0 0"/>
        <geometry>
          <cylinder radius = "0.005" length = "0.1471"/>
        </geometry>
          <material name = "red"/>
        </visual>
        <collision>
          <origin xyz = "0 0 0" rpy = "0 0 0"/>
          <geometry>
            <cylinder radius = "0.005" length = "0.1471"/>
          </geometry>
            <material name = "red"/>
        </collision>
      <inertial>
        <origin xyz = "0 0 0" rpy = "0 0 0"/>
        <mass value=""/>
        <inertia
          ixx="" ixy="" ixz=""
          iyy="" iyz=""
          izz=""/>
      </inertial>
    </link>  -->


     <!-- M10 Screw Linkage to Tibia -->
   <link name = "M10LinkageFemur1_1_1">
      <visual>
        <origin xyz = "0 0 -.105" rpy = "0 0 0"/>
        <geometry>
          <cylinder radius = "0.005" length = "0.21"/>
        </geometry>
          <material name = "grey"/>
        </visual>
        <collision>
          <origin xyz = "0 0 0" rpy = "0 0 0"/>
          <geometry>
            <cylinder radius = "0.005" length = "0.21"/>
          </geometry>
            <material name = "grey"/>
        </collision>
      <inertial>
        <origin xyz = "0 0 -0.105" rpy = "0 0 0"/>
        <mass value="0.1"/>
        <inertia
          ixx="0.1" ixy="0" ixz="0"
          iyy="0" iyz="0"
          izz="0"/>
      </inertial>
    </link>
     <!-- <link name = "M10LinkageFemur1_1_2">
      <visual>
        <origin xyz = "0 0 0" rpy = "0 0 0"/>
        <geometry>
          <cylinder radius = "0.005" length = "0.105"/>
        </geometry>
          <material name = "grey"/>
        </visual>
        <collision>
          <origin xyz = "0 0 0" rpy = "0 0 0"/>
          <geometry>
            <cylinder radius = "0.005" length = "0.21"/>
          </geometry>
            <material name = "grey"/>
        </collision>
      <inertial>
        <origin xyz = "0 0 0" rpy = "0 0 0"/>
        <mass value="0.1"/>
        <inertia
          ixx="0.1" ixy="0" ixz="0"
          iyy="0" iyz="0"
          izz="0"/>
      </inertial>
    </link>  -->
<!-- 
    <link name = "M10LinkageTibia1.2">
      <visual>
        <origin xyz = "0 0 0" rpy = "0 0 0"/>
        <geometry>
          <cylinder radius = "0.005" length = "0.21"/>
        </geometry>
          <material name = "red"/>
        </visual>
        <collision>
          <origin xyz = "0 0 0" rpy = "0 0 0"/>
          <geometry>
            <cylinder radius = "0.005" length = "0.21"/>
          </geometry>
            <material name = "red"/>
        </collision>
      <inertial>
        <origin xyz = "0 0 0" rpy = "0 0 0"/>
        <mass value="0.1"/>
        <inertia
          ixx="0" ixy="0" ixz="0"
          iyy="0" iyz="0"
          izz="0"/>
      </inertial>
    </link>    -->

    <!-- M10 Screw Linkage to Femur -->
    <!-- <link name = "M10LinkageFemur1.1">
      <visual>
        <origin xyz = "0 0 0" rpy = "0 0 0"/>
        <geometry>
          <cylinder radius = "0.005" length = "0.14"/>
        </geometry>
          <material name = "red"/>
        </visual>
        <collision>
          <origin xyz = "0 0 0" rpy = "0 0 0"/>
          <geometry>
            <cylinder radius = "0.005" length = "0.14"/>
          </geometry>
            <material name = "red"/>
        </collision>
      <inertial>
        <origin xyz = "0 0 0" rpy = "0 0 0"/>
        <mass value=""/>
        <inertia
          ixx="" ixy="" ixz=""
          iyy="" iyz=""
          izz=""/>
      </inertial>
    </link>

    <link name = "M10LinkageFemur1.2">
      <visual>
        <origin xyz = "0 0 0" rpy = "0 0 0"/>
        <geometry>
          <cylinder radius = "0.005" length = "0.14"/> -->
        <!-- </geometry>
          <material name = "red"/>
        </visual>
        <collision>
          <origin xyz = "0 0 0" rpy = "0 0 0"/>
          <geometry>
            <cylinder radius = "0.005" length = "0.14"/>
          </geometry>
            <material name = "red"/>
        </collision>
      <inertial>
        <origin xyz = "0 0 0" rpy = "0 0 0"/>
        <mass value=""/>
        <inertia
          ixx="" ixy="" ixz=""
          iyy="" iyz=""
          izz=""/>
      </inertial>
    </link> -->


<link name = "screwbox_1_1">
      <visual>
        <origin xyz = "0 0 0" rpy = "0 0 0"/>
        <geometry>
          <box size = ".06 0.02 .042"/>
          </geometry>
          <material name = "grey"/>
      </visual>
        <collision>
          <origin xyz = "0 0 0" rpy = "0 0 0"/>
          <geometry>
            <box size = ".06 0.02 .042"/>
            </geometry>
            <material name = "grey"/>
          </collision>
      <inertial>
      <origin xyz = "0 0 0" rpy = "0 0 0"/>
        <mass value="0.187164"/>
        <inertia
          ixx="1" ixy="1" ixz="1"
          iyy="1" iyz="1"
          izz="1"/>
      </inertial>
   </link> 
<link name = "screwbox_1_2">
      <visual>
        <origin xyz = "0 0 0" rpy = "0 0 0"/>
        <geometry>
          <box size = ".06 0.02 .042"/>
          </geometry>
          <material name = "grey"/>
      </visual>
        <collision>
          <origin xyz = "0 0 0" rpy = "0 0 0"/>
          <geometry>
            <box size = ".06 0.02 .042"/>
            </geometry>
            <material name = "grey"/>
          </collision>
      <inertial>
      <origin xyz = "0 0 0" rpy = "0 0 0"/>
        <mass value="0.187164"/>
        <inertia
          ixx="1" ixy="1" ixz="1"
          iyy="1" iyz="1"
          izz="1"/>
      </inertial>
   </link> 
   <link name = "screwbox_1_3">
      <visual>
        <origin xyz = "0 0 0" rpy = "0 0 0"/>
        <geometry>
          <box size = ".06 0.02 .042"/>
          </geometry>
          <material name = "grey"/>
      </visual>
        <collision>
          <origin xyz = "0 0 0" rpy = "0 0 0"/>
          <geometry>
            <box size = ".06 0.02 .042"/>
            </geometry>
            <material name = "grey"/>
          </collision>
      <inertial>
      <origin xyz = "0 0 0" rpy = "0 0 0"/>
        <mass value="0.187164"/>
        <inertia
          ixx="1" ixy="1" ixz="1"
          iyy="1" iyz="1"
          izz="1"/>
      </inertial>
   </link>

   <link name = "screwbox_1_4">
      <visual>
        <origin xyz = "0 0 0" rpy = "0 0 0"/>
        <geometry>
          <box size = ".06 0.02 .042"/>
          </geometry>
          <material name = "grey"/>
      </visual>
        <collision>
          <origin xyz = "0 0 0" rpy = "0 0 0"/>
          <geometry>
            <box size = ".06 0.02 .042"/>
            </geometry>
            <material name = "grey"/>
          </collision>
      <inertial>
      <origin xyz = "0 0 0" rpy = "0 0 0"/>
        <mass value="0.187164"/>
        <inertia
          ixx="1" ixy="1" ixz="1"
          iyy="1" iyz="1"
          izz="1"/>
      </inertial>
   </link>

   <!-- M10 Connected to Body -->
 <link name = "M10Body1">
      <visual>
        <origin xyz = "0 0 0" rpy = "0 0 0"/>
        <geometry>
          <cylinder radius = "0.005" length = "0.185"/>
        </geometry>
          <material name = "grey"/>
        </visual>
        <collision>
          <origin xyz = "0 0 0" rpy = "0 0 0"/>
          <geometry>
            <cylinder radius = "0.005" length = "0.21"/>
          </geometry>
            <material name = "grey"/>
        </collision>
      <inertial>
        <origin xyz = "0 0 0" rpy = "0 0 0"/>
        <mass value="0.1"/>
        <inertia
          ixx="0.1" ixy="0" ixz="0"
          iyy="0" iyz="0"
          izz="0"/>
      </inertial>
    </link>

  <!-- JOINTS -->
  <!-- Child's COG is referenced from the parent's origin -->

    <joint name = "dummy_joint" type = "fixed">
        <parent link = "openDog_body"/>
        <child link  = "dummy_mass"/>
        <origin xyz = "0 0 0.7" rpy = "0 0 0"/>
    </joint>

    <joint name="hip_joint_1" type="fixed">
        <parent link="openDog_body"/>
        <child link="hip_tube_1"/>
        <origin xyz="-0.226 0.2825 0.7" rpy="0 0 0"/>
    </joint>
<!-- 
    <joint name="hip_joint_2" type="fixed">
        <parent link="openDog_body"/>
        <child link="hip_tube_2"/>
        <origin xyz="0.226 0.2825 0.7" rpy="0 0 0"/>
    </joint> -->
<!-- 
    <joint name="hip_joint_3" type="fixed">
        <parent link="openDog_body"/>
        <child link="hip_tube_3"/>
        <origin xyz="-0.226 -0.2825 0.7" rpy="0 0 0"/>
    </joint> -->
<!-- 
    <joint name="hip_joint_4" type="fixed">
        <parent link="openDog_body"/>
        <child link="hip_tube_4"/>
        <origin xyz="0.226 -0.2825 0.7" rpy="0 0 0"/>
    </joint> -->

    <joint name="femur_joint1" type="revolute">
        <parent link="hip_tube_1"/>
        <child link="upper_extrusion_leg1"/>
        <origin xyz="-0.05 0 0" rpy="1.5708 -3.14 1.5708"/>
        <limit lower="-1.579" upper="-0.567" effort="5000" velocity="1.0"/>
        <axis xyz="0 0 1"/>
    </joint>

    <transmission name="simple_trans0">
  <type>transmission_interface/SimpleTransmission</type>
  <joint name="femur_joint1">
    <hardwareInterface>hardware_interface/EffortJointInterface</hardwareInterface>
  </joint>
  <actuator name="motor_1">
    <mechanicalReduction>1</mechanicalReduction>
    <hardwareInterface>hardware_interface/EffortJointInterface</hardwareInterface>
  </actuator>
</transmission> 
<!-- 

    <joint name="femur_joint2" type="revolute">
        <parent link="hip_tube_2"/>
        <child link="upper_extrusion_leg2"/>
        <origin xyz="0.05 0 0" rpy="1.5708 -3.14 1.5708"/>
        <limit lower="-1.579" upper="-0.567" effort="5000" velocity="1.0"/>
        <axis xyz="0 0 1"/>
    </joint>

    <transmission name="simple_trans1">
  <type>transmission_interface/SimpleTransmission</type>
  <joint name="femur_joint2">
    <hardwareInterface>hardware_interface/EffortJointInterface</hardwareInterface>
  </joint>
  <actuator name="motor_2">  -->
    <!-- <mechanicalReduction>1</mechanicalReduction>
    <hardwareInterface>hardware_interface/EffortJointInterface</hardwareInterface>
  </actuator>
</transmission>

    <joint name="femur_joint3" type="revolute">
        <parent link="hip_tube_3"/>
        <child link="upper_extrusion_leg3"/>
        <origin xyz="-0.05 0 0" rpy="1.5708 -3.14 1.5708"/>
        <limit lower="-1.579" upper="-0.567" effort="5000" velocity="1.0"/>
        <axis xyz="0 0 1"/>
    </joint>

    <transmission name="simple_trans2">
  <type>transmission_interface/SimpleTransmission</type>
  <joint name="femur_joint3">
    <hardwareInterface>hardware_interface/EffortJointInterface</hardwareInterface>
  </joint>
  <actuator name="motor_3">
    <mechanicalReduction>1</mechanicalReduction>
    <hardwareInterface>hardware_interface/EffortJointInterface</hardwareInterface>
  </actuator> -->
<!-- </transmission>

    <joint name="femur_joint4" type="revolute">
        <parent link="hip_tube_4"/>
        <child link="upper_extrusion_leg4"/>
        <origin xyz="0.05 0 0" rpy="1.5708 -3.14 1.5708"/>
        <limit lower="-1.579" upper="-0.567" effort="5000" velocity="1.0"/>
        <axis xyz="0 0 1"/>
    </joint>

    <transmission name="simple_trans3">
  <type>transmission_interface/SimpleTransmission</type>
  <joint name="femur_joint4">
    <hardwareInterface>hardware_interface/EffortJointInterface</hardwareInterface>
  </joint>
  <actuator name="motor_4">
    <mechanicalReduction>1</mechanicalReduction>
    <hardwareInterface>hardware_interface/EffortJointInterface</hardwareInterface>
  </actuator> -->
<!-- < </transmission> -->

    <joint name = "knee_joint_leg1" type = "revolute">
        <parent link = "upper_extrusion_leg1"/>
        <child link = "lower_extrusion_leg1"/>
        <origin xyz="0 0.39 0" rpy="0 0 0"/>

        <limit effort="5000"  lower="1.352" upper="2.8715" velocity="1.0"/>
        <axis xyz="0 0 5"/>

    </joint>

      <transmission name="simple_trans4"> 
  <type>transmission_interface/SimpleTransmission</type>
  <joint name="knee_joint_leg1">
    <hardwareInterface>hardware_interface/EffortJointInterface</hardwareInterface>
  </joint>
  <actuator name="motor_5">
    <mechanicalReduction>1</mechanicalReduction>
    <hardwareInterface>hardware_interface/EffortJointInterface</hardwareInterface>
  </actuator> 
</transmission> 
<!-- 
    <joint name = "knee_joint_leg2" type = "revolute">
        <parent link = "upper_extrusion_leg2"/>
        <child link = "lower_extrusion_leg2"/>
        <origin xyz="0 0.39 0" rpy="0 0 0"/>
        <limit effort="5000"  lower="1.352" upper="2.8715" velocity="1.0"/>
        <axis xyz="0 0 1"/>

    </joint> -->

    <!-- <transmission name="simple_trans5">
  <type>transmission_interface/SimpleTransmission</type>
  <joint name="knee_joint_leg2">
    <hardwareInterface>hardware_interface/EffortJointInterface</hardwareInterface>
  </joint>
  <actuator name="motor_6">
    <mechanicalReduction>1</mechanicalReduction>
    <hardwareInterface>hardware_interface/EffortJointInterface</hardwareInterface>
  </actuator>
</transmission>   -->

    <!-- <joint name = "knee_joint_leg3" type = "revolute">
        <parent link = "upper_extrusion_leg3"/>
        <child link = "lower_extrusion_leg3"/>
        <origin xyz="0 0.39 0" rpy="0 0 0"/>
        <limit effort="5000"  lower="1.352" upper="2.8715" velocity="1.0"/>
        <axis xyz="0 0 1"/>
    </joint>

    <transmission name="simple_trans6">
  <type>transmission_interface/SimpleTransmission</type>
  <joint name="knee_joint_leg3">
    <hardwareInterface>hardware_interface/EffortJointInterface</hardwareInterface>
  </joint>
  <actuator name="motor_7">
    <mechanicalReduction>1</mechanicalReduction>
    <hardwareInterface>hardware_interface/EffortJointInterface</hardwareInterface>
  </actuator>
</transmission> -->


    <!-- <joint name = "knee_joint_leg4" type = "revolute">
        <parent link = "upper_extrusion_leg4"/>
        <child link = "lower_extrusion_leg4"/>
        <origin xyz="0 0.39 0" rpy="0 0 0 "/>
        <limit effort="5000"  lower="1.352" upper="2.8715" velocity="1.0"/>
        <axis xyz="0 0 1"/>
    </joint>

    <transmission name="simple_trans7">
  <type>transmission_interface/SimpleTransmission</type>
  <joint name="knee_joint_leg4">
    <hardwareInterface>hardware_interface/EffortJointInterface</hardwareInterface>
  </joint>
  <actuator name="motor_8">
    <mechanicalReduction>1</mechanicalReduction>
    <hardwareInterface>hardware_interface/EffortJointInterface</hardwareInterface>
  </actuator>
</transmission> --> 


<!-- KNEE-LOWER EXTRUSION FIXED JOINTS  -->

    <joint name = "lowerex_knee_leg1" type = "fixed">
        <parent link = "lower_extrusion_leg1"/>
        <child link = "knee1"/>
        <origin xyz = "-0.028 .1 0" rpy = "0 1.57 1.57"/>
    </joint>

<!-- <<joint name = "lowerex_knee_leg3" type = "fixed">
      <parent link = "lower_extrusion_leg3"/>
      <child link = "knee3"/>
      <origin xyz = "0 0 0.7" rpy = "0 0 0"/>
  </joint> -->
<!-- 
  <joint name = "lowerex_knee_leg4" type = "fixed">
        <parent link = "lower_extrusion_leg4"/>
        <child link = "knee4"/>
        <origin xyz = "0 0 0.7" rpy = "0 0 0"/>
    </joint>   -->


    <!-- Knee-M10 Joint -->
      <joint name = "kneeM10_1_1" type = "fixed">
          <parent link = "knee1"/>
          <child link = "M10Knee1_1"/>
          <origin xyz = "0 0 .03" rpy = "0 1.5 0"/>
      </joint>

      <!-- <joint name = "kneeM10_2" type = "fixed">
            <parent link = "knee2"/>
            <child link = "M10Knee2"/>
            <origin xyz = "0 0 0" rpy = "0 0 0"/>
        </joint>  -->


    <!-- Slide Block-M10 -->
    <!-- femur upper -->
     <joint name = "SlideBlockM10_1_1" type = "fixed">
          <parent link = "SlideBlock1_1"/>
          <child link = "M10ScrewFemur1_1"/>
          <origin xyz = "0 -.05 0" rpy = "1.57 0 0"/>
      </joint> 

       <joint name = "SlideBlockM10_1_2" type = "fixed">
            <parent link = "SlideBlock1_1"/>
            <child link = "M10ScrewFemur1_2"/>
            <origin xyz = "0 .05 0" rpy = "1.57 0 0"/>
        </joint>  

      <!-- femur lower -->
      <joint name = "SlideBlockM10_1_3" type = "fixed">
            <parent link = "SlideBlock1_2"/>
            <child link = "M10ScrewFemur1_3"/>
            <origin xyz = "0 -.05 0" rpy = "1.57 0 0"/>
        </joint>

         <joint name = "SlideBlockM10_1_4" type = "fixed">
              <parent link = "SlideBlock1_2"/>
              <child link = "M10ScrewFemur1_4"/>
              <origin xyz = "0 .05 0" rpy = "1.57 0 0"/>
          </joint>  


    <!-- Slide Block M10 to upper femur Linkage -->
<!--     
     <joint name = "M10FemurLinkage1.1" type = "revolute">
        <parent link = "M10ScrewFemur1.1"/>
        <child link = "M10LinkageFemur1.1"/>
        <origin xyz="0 0 0" rpy="0 0 0 "/>
        <limit effort="5000"  lower="1.352" upper="2.8715" velocity="1.0"/>
        <axis xyz="0 0 0"/>
    </joint> -->
<!-- 
    <joint name = "M10TibiaLinkage1.2" type = "revolute">
        <parent link = "M10ScrewTibia1.2"/>
        <child link = "M10LinkageTibia1.2"/>
        <origin xyz="0 0 0" rpy="0 0 0 "/>
        <limit effort="5000"  lower="1.352" upper="2.8715" velocity="1.0"/>
        <axis xyz="0 0 0"/>
    </joint>   -->


     <!-- Slide Block M10 to Femur Linkagec -->
    <!-- <joint name = "M10FemurLinkage1_1" type = "revolute">
        <parent link = "M10ScrewFemur1_3"/>
        <child link = "M10LinkageFemur1_1_1"/>
        <origin xyz="0 0 0.025" rpy="1.57 0 0 "/>
        <limit effort="5000"  lower="1.352" upper="2.8715" velocity="1.0"/>
        <axis xyz="0 1 0"/>
    </joint> -->

    <!-- <joint name = "M10FemurLinkage1.2" type = "revolute">
        <parent link = "M10ScrewFemur1.2"/>
        <child link = "M10LinkageFemur1.2"/>
        <origin xyz="0 0 0" rpy="0 0 0 "/>
        <limit effort="5000"  lower="1.352" upper="2.8715" velocity="1.0"/>
        <axis xyz="0 0 0"/> 
        <joint>
        -->



     <!-- Knee M10 to Tibia Linkage -->
      <joint name = "M10KneeLinkage1_1" type = "revolute">
        <parent link = "M10ScrewFemur1_3"/>
        <child link = "M10LinkageFemur1_1_1"/>
        <origin xyz=" 0 0 -0.015" rpy="1.57 0 0 "/>
        <limit effort="5000"  lower="1.352" upper="2.8715" velocity="1.0"/>
        <axis xyz="0 1 0"/>
    </joint>
  
     <joint name = "M10KneeLinkage1_2" type = "revolute">
        <parent link = "M10Knee1_1"/>
        <child link = "M10LinkageFemur1_1_1"/>
        <origin xyz="0 0 0.022" rpy="0 1.57 0 "/>
         <limit effort="5000"  lower="1.352" upper="2.8715" velocity="1.0"/>
        <axis xyz="1 0 0"/>
    </joint>     

<!-- closed loop plugin -->
 <gazebo>
  <plugin name="Myrobot_ClosedLoopPlugin" filename="libpegasus_gazebo_closed_loop_plugin.so">
    <joint>M10KneeLinkage1_2</joint>
    <child>M10LinkageFemur1_1_1</child> 
    <parent>M10Knee1_1</parent>
    <position>0 0.0 0.0</position>
    <rotation>0 0 0.00</rotation>
  </plugin>
</gazebo>   

<!-- Screwbox to femur -->
<joint name = "Screwbox_Femur1_1" type = "fixed">
        <parent link = "upper_extrusion_leg1"/>
        <child link = "screwbox_1_1"/>
        <origin xyz = "0.04 .07 .013" rpy = "0 0 0"/>
    </joint>

<joint name = "Screwbox_Femur1_2" type = "fixed">
        <parent link = "upper_extrusion_leg1"/>
        <child link = "screwbox_1_2"/>
        <origin xyz = "0.04 .31 .013" rpy = "0 0 0"/>
    </joint>

    <joint name = "Screwbox_Femur1_3" type = "fixed">
        <parent link = "upper_extrusion_leg1"/>
        <child link = "screwbox_1_3"/>
        <origin xyz = "-0.04 .34 .013" rpy = "0 0 0"/>
    </joint>
    <joint name = "Screwbox_Femur1_4" type = "fixed">
        <parent link = "upper_extrusion_leg1"/>
        <child link = "screwbox_1_4"/>
        <origin xyz = "-0.04 .10 .013" rpy = "0 0 0"/>
    </joint>
    
    <!-- Screw box to cylinder -->
    <!-- upper femur -->
<joint name = "Screwbox_cylinder1_1" type = "fixed">
        <parent link = "screwbox_1_1"/>
        <child link = "Screw1"/>
        <origin xyz = "0 .12 0" rpy = "1.57 0 0"/>
    </joint>

    <!-- lower femur -->
<joint name = "Screwbox_cylinder1_2" type = "fixed">
        <parent link = "screwbox_1_4"/>
        <child link = "Screw2"/>
        <origin xyz = "0 .12 0" rpy = "1.57 0 0"/>
    </joint>


    <!-- Slide Block on Cyclinder -->
    
    <!-- upper femur -->
    <joint name="slider1_1" type="prismatic">
    <parent link="Screw1"/>
    <child link="SlideBlock1_1"/>
    <origin xyz="0 0 0" rpy="0 0 0"/>
    <axis xyz="0 0 1"/>
    <limit effort="1000.0" lower="-0.08" upper="0.08" velocity="0.5"/>
  </joint>

<!-- lower femure -->

 <joint name="slider1_2" type="prismatic">
    <parent link="Screw2"/>
    <child link="SlideBlock1_2"/>
    <origin xyz="0 0 0" rpy="0 0 0"/>
    <axis xyz="0 0 1"/>
    <limit effort="1000.0" lower="-0.08" upper="0.08" velocity="0.5"/>
  </joint>

<!-- Long M10 Screw to Body -->
  <joint name="M10Body1" type="fixed">
        <parent link="openDog_body"/>
        <child link="M10Body1"/>
        <origin xyz="-0.226 0.1841 0.7299" rpy="0 1.57 0"/>
    </joint>

    <!-- Upper Leg to Body M10 -->


</robot> 